[2020-06-29 22:24:10,230] {taskinstance.py:669} INFO - Dependencies all met for <TaskInstance: covid_data_dag.move_data_to_sql 2020-06-29T16:50:11.128574+00:00 [queued]>
[2020-06-29 22:24:10,239] {taskinstance.py:669} INFO - Dependencies all met for <TaskInstance: covid_data_dag.move_data_to_sql 2020-06-29T16:50:11.128574+00:00 [queued]>
[2020-06-29 22:24:10,239] {taskinstance.py:879} INFO - 
--------------------------------------------------------------------------------
[2020-06-29 22:24:10,239] {taskinstance.py:880} INFO - Starting attempt 1 of 2
[2020-06-29 22:24:10,239] {taskinstance.py:881} INFO - 
--------------------------------------------------------------------------------
[2020-06-29 22:24:10,246] {taskinstance.py:900} INFO - Executing <Task(BashOperator): move_data_to_sql> on 2020-06-29T16:50:11.128574+00:00
[2020-06-29 22:24:10,248] {standard_task_runner.py:53} INFO - Started process 28982 to run task
[2020-06-29 22:24:10,290] {logging_mixin.py:112} INFO - Running %s on host %s <TaskInstance: covid_data_dag.move_data_to_sql 2020-06-29T16:50:11.128574+00:00 [running]> localhost.localdomain
[2020-06-29 22:24:10,299] {bash_operator.py:82} INFO - Tmp dir root location: 
 /tmp
[2020-06-29 22:24:10,300] {bash_operator.py:103} INFO - Temporary script location: /tmp/airflowtmp_qikgh5t/move_data_to_sqlswcldkxn
[2020-06-29 22:24:10,300] {bash_operator.py:115} INFO - Running command: /bin/bash HADOOP_USER_NAME=shailander sqoop export --connect jdbc:mysql://localhost/test -username root  --columns 'active, confirmed, deaths, recovered, state,' --table covid_data  --hcatalog-table data_partition  --input-fields-terminated-by ',' -m 1
[2020-06-29 22:24:10,306] {bash_operator.py:122} INFO - Output:
[2020-06-29 22:24:10,312] {bash_operator.py:126} INFO - /bin/bash: HADOOP_USER_NAME=shailander: No such file or directory
[2020-06-29 22:24:10,312] {bash_operator.py:128} INFO - Command exited with return code 127
[2020-06-29 22:24:10,318] {taskinstance.py:1145} ERROR - Bash command failed
Traceback (most recent call last):
  File "/home/nineleaps/PycharmProjects/ProjectX/venv/lib/python3.8/site-packages/airflow/models/taskinstance.py", line 983, in _run_raw_task
    result = task_copy.execute(context=context)
  File "/home/nineleaps/PycharmProjects/ProjectX/venv/lib/python3.8/site-packages/airflow/operators/bash_operator.py", line 134, in execute
    raise AirflowException("Bash command failed")
airflow.exceptions.AirflowException: Bash command failed
[2020-06-29 22:24:10,321] {taskinstance.py:1168} INFO - Marking task as UP_FOR_RETRY
[2020-06-29 22:24:20,225] {logging_mixin.py:112} INFO - [2020-06-29 22:24:20,225] {local_task_job.py:103} INFO - Task exited with return code 1
